
<!-- This URDF was automatically created by SolidWorks to URDF Exporter! Originally created by Stephen Brawner (brawner@gmail.com) 
     Commit Version: 1.6.0-4-g7f85cfe  Build Version: 1.6.7995.38578
     For more information, please see http://wiki.ros.org/sw_urdf_exporter -->
<robot
  name="astra_arm_urdf">
  <link
    name="base_link">
    <inertial>
      <origin
        xyz="-3.08444532333696E-05 0.00118382469675537 0.0391133064626048"
        rpy="0 0 0" />
      <mass
        value="0.21714940667968" />
      <inertia
        ixx="0.000199893756705658"
        ixy="9.78241783510233E-08"
        ixz="-7.79432582355636E-08"
        iyy="0.000197792028989822"
        iyz="-6.6812305798477E-06"
        izz="0.000273059596803161" />
    </inertial>
    <visual>
      <origin
        xyz="0 0 0"
        rpy="0 0 0" />
      <geometry>
        <mesh
          filename="package://astra_arm_urdf/meshes/base_link.STL" />
      </geometry>
      <material
        name="">
        <color
          rgba="1 1 1 1" />
      </material>
    </visual>
    <collision>
      <origin
        xyz="0 0 0"
        rpy="0 0 0" />
      <geometry>
        <mesh
          filename="package://astra_arm_urdf/meshes/base_link.STL" />
      </geometry>
    </collision>
  </link>
  <link
    name="shoulder_link">
    <inertial>
      <origin
        xyz="-7.50059831744476E-08 0.0125350268571897 0.0183608533773389"
        rpy="0 0 0" />
      <mass
        value="0.123597949087119" />
      <inertia
        ixx="7.65097456410541E-05"
        ixy="2.77787381058924E-10"
        ixz="6.67658494872229E-11"
        iyy="8.32883912152094E-05"
        iyz="-7.68878516719141E-06"
        izz="7.65397018405884E-05" />
    </inertial>
    <visual>
      <origin
        xyz="0 0 0"
        rpy="0 0 0" />
      <geometry>
        <mesh
          filename="package://astra_arm_urdf/meshes/shoulder_link.STL" />
      </geometry>
      <material
        name="">
        <color
          rgba="1 1 1 1" />
      </material>
    </visual>
    <collision>
      <origin
        xyz="0 0 0"
        rpy="0 0 0" />
      <geometry>
        <mesh
          filename="package://astra_arm_urdf/meshes/shoulder_link.STL" />
      </geometry>
    </collision>
  </link>
  <joint
    name="shoulder_joint"
    type="revolute">
    <origin
      xyz="0 0 0.050402"
      rpy="0 0 0" />
    <parent
      link="base_link" />
    <child
      link="shoulder_link" />
    <axis
      xyz="0 0 1" />
    <limit
      lower="-1.57"
      upper="1.57"
      effort="10.5"
      velocity="1.5" />
  </joint>
  <link
    name="upperarm_link">
    <inertial>
      <origin
        xyz="-0.000712004722758494 -0.00630711901343494 0.0699991316734497"
        rpy="0 0 0" />
      <mass
        value="0.137956897450908" />
      <inertia
        ixx="0.000412802425063209"
        ixy="-1.54156023193934E-09"
        ixz="3.8766709137467E-06"
        iyy="0.000431598972020418"
        iyz="2.53724770390078E-09"
        izz="3.08732568954117E-05" />
    </inertial>
    <visual>
      <origin
        xyz="0 0 0"
        rpy="0 0 0" />
      <geometry>
        <mesh
          filename="package://astra_arm_urdf/meshes/upperarm_link.STL" />
      </geometry>
      <material
        name="">
        <color
          rgba="1 1 1 1" />
      </material>
    </visual>
    <collision>
      <origin
        xyz="0 0 0"
        rpy="0 0 0" />
      <geometry>
        <mesh
          filename="package://astra_arm_urdf/meshes/upperarm_link.STL" />
      </geometry>
    </collision>
  </link>
  <joint
    name="upperarm_joint"
    type="revolute">
    <origin
      xyz="0 -0.004 0.03855"
      rpy="0 0 0" />
    <parent
      link="shoulder_link" />
    <child
      link="upperarm_link" />
    <axis
      xyz="0 -1 0" />
    <limit
      lower="-1.57"
      upper="1.57"
      effort="10.5"
      velocity="1.5" />
  </joint>
  <link
    name="elbow_link">
    <inertial>
      <origin
        xyz="0.0282843572655105 0.0171086319271421 4.09041417299694E-05"
        rpy="0 0 0" />
      <mass
        value="0.122761924125554" />
      <inertia
        ixx="2.77007139666344E-05"
        ixy="-5.07725389371186E-07"
        ixz="-2.2435112906729E-07"
        iyy="0.000127148823996402"
        iyz="-9.22811188708679E-09"
        izz="0.000117815411609115" />
    </inertial>
    <visual>
      <origin
        xyz="0 0 0"
        rpy="0 0 0" />
      <geometry>
        <mesh
          filename="package://astra_arm_urdf/meshes/elbow_link.STL" />
      </geometry>
      <material
        name="">
        <color
          rgba="1 1 1 1" />
      </material>
    </visual>
    <collision>
      <origin
        xyz="0 0 0"
        rpy="0 0 0" />
      <geometry>
        <mesh
          filename="package://astra_arm_urdf/meshes/elbow_link.STL" />
      </geometry>
    </collision>
  </link>
  <joint
    name="elbow_joint"
    type="revolute">
    <origin
      xyz="-0.0014208 0.004 0.13999"
      rpy="0 0 0" />
    <parent
      link="upperarm_link" />
    <child
      link="elbow_link" />
    <axis
      xyz="0 1 0" />
    <limit
      lower="-1.57"
      upper="1.57"
      effort="10.5"
      velocity="1.5" />
  </joint>
  <link
    name="wrist_link">
    <inertial>
      <origin
        xyz="0.0198135251298811 -0.00246462048019957 0.00507245140955287"
        rpy="0 0 0" />
      <mass
        value="0.0275804642723953" />
      <inertia
        ixx="3.41874740135694E-06"
        ixy="4.27967014050992E-07"
        ixz="-1.12001078956374E-08"
        iyy="6.50091950101727E-06"
        iyz="3.16684120748732E-09"
        izz="5.80153585835653E-06" />
    </inertial>
    <visual>
      <origin
        xyz="0 0 0"
        rpy="0 0 0" />
      <geometry>
        <mesh
          filename="package://astra_arm_urdf/meshes/wrist_link.STL" />
      </geometry>
      <material
        name="">
        <color
          rgba="1 1 1 1" />
      </material>
    </visual>
    <collision>
      <origin
        xyz="0 0 0"
        rpy="0 0 0" />
      <geometry>
        <mesh
          filename="package://astra_arm_urdf/meshes/wrist_link.STL" />
      </geometry>
    </collision>
  </link>
  <joint
    name="wrist_joint"
    type="revolute">
    <origin
      xyz="0.1057 0.01435 -0.0051"
      rpy="0 0 0" />
    <parent
      link="elbow_link" />
    <child
      link="wrist_link" />
    <axis
      xyz="-1 0 0" />
    <limit
      lower="-1.57"
      upper="1.57"
      effort="10.5"
      velocity="1.5" />
  </joint>
  <link
    name="extra_wrist_link">
    <inertial>
      <origin
        xyz="0.0262793912938347 0.0046418443676678 0.00206186061675029"
        rpy="0 0 0" />
      <mass
        value="0.0227046882547889" />
      <inertia
        ixx="3.29041243163955E-06"
        ixy="-5.46124141762123E-07"
        ixz="-8.30851199579705E-07"
        iyy="5.33636886986773E-06"
        iyz="-4.65500232236998E-08"
        izz="6.67442856376792E-06" />
    </inertial>
    <visual>
      <origin
        xyz="0 0 0"
        rpy="0 0 0" />
      <geometry>
        <mesh
          filename="package://astra_arm_urdf/meshes/extra_wrist_link.STL" />
      </geometry>
      <material
        name="">
        <color
          rgba="1 1 1 1" />
      </material>
    </visual>
    <collision>
      <origin
        xyz="0 0 0"
        rpy="0 0 0" />
      <geometry>
        <mesh
          filename="package://astra_arm_urdf/meshes/extra_wrist_link.STL" />
      </geometry>
    </collision>
  </link>
  <joint
    name="extra_wrist_joint"
    type="revolute">
    <origin
      xyz="0.0284 -0.01685 0.0051"
      rpy="0 0 0" />
    <parent
      link="wrist_link" />
    <child
      link="extra_wrist_link" />
    <axis
      xyz="0 1 0" />
    <limit
      lower="-1.57"
      upper="1.57"
      effort="10.5"
      velocity="1.5" />
  </joint>
  <link
    name="ee_link">
    <inertial>
      <origin
        xyz="-0.051955968606695 -0.000885887245608952 0.00254263682994083"
        rpy="0 0 0" />
      <mass
        value="0.0209019024310684" />
      <inertia
        ixx="5.38316186283137E-07"
        ixy="-2.08546966880991E-08"
        ixz="1.28457020321453E-08"
        iyy="4.69382135625053E-06"
        iyz="2.62574718208672E-09"
        izz="5.05831144269527E-06" />
    </inertial>
    <visual>
      <origin
        xyz="0 0 0"
        rpy="0 0 0" />
      <geometry>
        <mesh
          filename="package://astra_arm_urdf/meshes/ee_link.STL" />
      </geometry>
      <material
        name="">
        <color
          rgba="0.792156862745098 0.819607843137255 0.933333333333333 1" />
      </material>
    </visual>
    <collision>
      <origin
        xyz="0 0 0"
        rpy="0 0 0" />
      <geometry>
        <mesh
          filename="package://astra_arm_urdf/meshes/ee_link.STL" />
      </geometry>
    </collision>
  </link>
  <joint
    name="ee_joint"
    type="fixed">
    <origin
      xyz="0.11955 0.0032766 0.0078437"
      rpy="0 0 0" />
    <parent
      link="extra_wrist_link" />
    <child
      link="ee_link" />
    <axis
      xyz="0 0 0" />
    <limit
      lower="0.5"
      upper="0.5"
      effort="10.5"
      velocity="1.5" />
  </joint>
  
  
    <link name="ee_rotation_x"/>
  <joint name="ee_rotation_joint_x" type="revolute">
    <origin xyz="0 0 0" rpy="0 0 0"/>
    <parent link="ee_link"/>
    <child link="ee_rotation_x"/>
    <axis xyz="1 0 0"/>
    <limit lower="-3.1416" upper="3.1416" effort="1" velocity="1"/>
  </joint>

</robot>
